Workbook

Sheet Cover
B1: Adani Group / Ambuja Cements & ACC — Merger Consequences Model
B2: INR crore unless stated. Deal announced 15-May-2022, completed 16-Sep-2022.
B4: How this workbook works
B5: Blue cells on a yellow background are inputs (all on the 'Inputs' sheet; synergy items on 'Synergies'; deal data on 'Precedents').
B6: Black cells are live Excel formulas. Change any input and the workbook recalculates.
B7: 'Checks' tests the model's integrity and reconciles every formula against the Python model (python run_model.py).
B8: 'Sensitivity' is static: each cell is a full re-run of the Python model with one input changed.
B9: 'Historicals' holds filed CY2019-CY2021 standalone figures used as the projection base.
B10: Assumptions are labelled [ASSUMPTION] with a rationale; filed data cite their source.
B12: Sources
B13: holcim_release | C13: Holcim media release, May-2022 — https://www.holcim.com/media/media-releases/holcim-india-business-acquired
B14: adani_release | C14: Adani media release, 16-Sep-2022 — https://www.adani.com/newsroom/media-releases/adani-becomes-indias-second-largest-cement-player
B15: bs_open_offer | C15: Business Standard, 10-Sep-2022 — https://www.business-standard.com/article/companies/ambuja-cements-acc-receive-lukewarm-response-from-public-shareholders-122091000362_1.html
B16: bs_refi | C16: Business Standard, 1-Dec-2022 — https://www.business-standard.com/article/companies/adani-group-to-refinance-ambuja-cement-acc-debt-worth-3-5-billion-122120100944_1.html
B17: screener_ambuja | C17: Ambuja standalone financials (company filings via Screener) — https://www.screener.in/company/AMBUJACEM/
B18: screener_acc | C18: ACC standalone financials (company filings via Screener) — https://www.screener.in/company/ACC/
B19: nse_prices | C19: NSE daily closes (Yahoo Finance history: AMBUJACEM.NS, ACC.NS, USDINR=X)
B20: bs_jaypee_2013 | C20: Business Standard, 12-Sep-2013 — https://www.business-standard.com/article/companies/birla-buys-jaypee-s-gujarat-cement-unit-for-rs-3-800-cr-113091200054_1.html
B21: bs_jaypee_2016 | C21: Business Standard, 5-Jul-2016 — https://www.business-standard.com/article/markets/jp-deal-big-leap-for-ultratech-116070501043_1.html
B22: bs_lafarge_2016 | C22: Business Standard, 11-Jul-2016 — https://www.business-standard.com/article/companies/nirma-cements-1-4-bn-lafarge-india-buyout-116071100403_1.html
B23: li_century_2018 | C23: Legally India, 22-May-2018 (EV) — https://www.legallyindia.com/corporatemna/trilegal-khaitan-vaish-on-ultratech-cem-s-buy-of-century-textile-s-cement-biz-20180522-9362 ; capacity per CARE Ratings report on UltraTech
B24: bs_binani_2018 | C24: Business Standard, 25-Dec-2019 (Kotak estimate of EV) — https://www.business-standard.com/amp/article/companies/ultratech-cement-street-watchful-on-valuations-of-new-acquisition-119122500555_1.html
B25: nuvoco_emami_2020 | C25: Nuvoco press release, Feb-2020 — https://admin.nuvoco.com/public/MediaRalationsDetails/Nirma%20Group%20announces%20the%20acquisition%20of%20Emami%20Cement%20-%20Feb%202020.pdf

Sheet Checks
B1: Checks
B2: Integrity checks (formulas) and Python reconciliation. Every row should read OK.
B3: OVERALL STATUS | C3: =IF(AND(COUNTIF(C5:C13,"OK")=9,COUNTIF(F17:F273,"OK")=257),"ALL CHECKS OK","CHECK FAILURES") -> ALL CHECKS OK
B4: Integrity checks
B5: Balance sheet balances | C5: =IF(ABS('Balance Sheet'!$C$13-'Balance Sheet'!$C$22)<1,"OK","FAIL") -> OK
B6: Sources = uses | C6: =IF(ABS('Deal & Financing'!$C$20-'Deal & Financing'!$C$13)<1,"OK","FAIL") -> OK
B7: Sponsor equity is positive | C7: =IF('Deal & Financing'!$C$19>0,"OK","FAIL") -> OK
B8: Look-through consideration = consideration paid | C8: =IF(ABS('PPA & Goodwill'!$C$22+'PPA & Goodwill'!$C$23-'Deal & Financing'!$C$10)<1,"OK","FAIL") -> OK
B9: Ownership ties to Adani release: Ambuja (±0.05pp) | C9: =IF(ABS('Deal & Financing'!$C$24-'Inputs'!$C$21)<0.0005,"OK","FAIL") -> OK
B10: Ownership ties to Adani release: ACC (±0.05pp) | C10: =IF(ABS('Deal & Financing'!$C$26-'Inputs'!$C$22)<0.0005,"OK","FAIL") -> OK
B11: Consideration within 3% of reported US$6.5bn | C11: =IF(ABS('Deal & Financing'!$C$11/'Inputs'!$C$20-1)<0.03,"OK","FAIL") -> OK
B12: Goodwill positive for both entities | C12: =IF(AND('PPA & Goodwill'!$C$26>0,'PPA & Goodwill'!$C$27>0),"OK","FAIL") -> OK
B13: Attributable + NCI = consolidated NI (all years) | C13: =IF(ABS(SUM('Pro Forma & Returns'!$D$23:$F$23)+SUM('Pro Forma & Returns'!$D$24:$F$24)-SUM('Pro Forma & Returns'!$D$15:$F$15))<1,"OK","FAIL") -> OK
B15: Python reconciliation (formula value vs Python model)
B16: Item | C16: Year | D16: Excel formula | E16: Python | F16: Status
B17: Ambuja shares bought from Holcim | D17: ='Deal & Financing'!$C$4 -> 125.31122 | E17: 125.31122 | F17: =IF(ABS(D17-E17)<0.000001,"OK","DIFF") -> OK
B18: ACC shares bought from Holcim (direct) | D18: ='Deal & Financing'!$C$5 -> 0.841344 | E18: 0.841344 | F18: =IF(ABS(D18-E18)<0.000001,"OK","DIFF") -> OK
B19: Holcim Ambuja stake | D19: ='Deal & Financing'!$C$6 -> 48244.818 | E19: 48244.818 | F19: =IF(ABS(D19-E19)<0.5,"OK","DIFF") -> OK
B20: Holcim direct ACC stake | D20: ='Deal & Financing'!$C$7 -> 1935.0912 | E20: 1935.0912 | F20: =IF(ABS(D20-E20)<0.5,"OK","DIFF") -> OK
B21: Ambuja open offer (shares tendered) | D21: ='Deal & Financing'!$C$8 -> 27.9895 | E21: 27.9895 | F21: =IF(ABS(D21-E21)<0.5,"OK","DIFF") -> OK
B22: ACC open offer (shares tendered) | D22: ='Deal & Financing'!$C$9 -> 934.03 | E22: 934.03 | F22: =IF(ABS(D22-E22)<0.5,"OK","DIFF") -> OK
B23: Total consideration | D23: ='Deal & Financing'!$C$10 -> 51141.929 | E23: 51141.929 | F23: =IF(ABS(D23-E23)<0.5,"OK","DIFF") -> OK
B24: Total consideration (US$ bn) | D24: ='Deal & Financing'!$C$11 -> 6.40475 | E24: 6.40475 | F24: =IF(ABS(D24-E24)<0.000001,"OK","DIFF") -> OK
B25: Transaction costs | D25: ='Deal & Financing'!$C$12 -> 511.41929 | E25: 511.41929 | F25: =IF(ABS(D25-E25)<0.5,"OK","DIFF") -> OK
B26: Total uses | D26: ='Deal & Financing'!$C$13 -> 51653.348 | E26: 51653.348 | F26: =IF(ABS(D26-E26)<0.5,"OK","DIFF") -> OK
B27: Acquisition debt (INR) | D27: ='Deal & Financing'!$C$16 -> 35932.5 | E27: 35932.5 | F27: =IF(ABS(D27-E27)<0.5,"OK","DIFF") -> OK
B28: of which bridge | D28: ='Deal & Financing'!$C$17 -> 27947.5 | E28: 27947.5 | F28: =IF(ABS(D28-E28)<0.5,"OK","DIFF") -> OK
B29: of which term loan | D29: ='Deal & Financing'!$C$18 -> 7985 | E29: 7985 | F29: =IF(ABS(D29-E29)<0.5,"OK","DIFF") -> OK
B30: Sponsor equity (balancing item) | D30: ='Deal & Financing'!$C$19 -> 15720.848 | E30: 15720.848 | F30: =IF(ABS(D30-E30)<0.5,"OK","DIFF") -> OK
B31: Total sources | D31: ='Deal & Financing'!$C$20 -> 51653.348 | E31: 51653.348 | F31: =IF(ABS(D31-E31)<0.5,"OK","DIFF") -> OK
B32: Adani stake in Ambuja | D32: ='Deal & Financing'!$C$24 -> 0.63146614 | E32: 0.63146614 | F32: =IF(ABS(D32-E32)<0.000001,"OK","DIFF") -> OK
B33: Adani direct stake in ACC | D33: ='Deal & Financing'!$C$25 -> 0.066424068 | E33: 0.066424068 | F33: =IF(ABS(D33-E33)<0.000001,"OK","DIFF") -> OK
B34: Adani-controlled stake in ACC (direct + via Ambuja) | D34: ='Deal & Financing'!$C$26 -> 0.56692407 | E34: 0.56692407 | F34: =IF(ABS(D34-E34)<0.000001,"OK","DIFF") -> OK
B35: Adani look-through economic stake in ACC | D35: ='Deal & Financing'!$C$27 -> 0.38247287 | E35: 0.38247287 | F35: =IF(ABS(D35-E35)<0.000001,"OK","DIFF") -> OK
B36: Ambuja premium to undisturbed close | D36: ='Deal & Financing'!$C$30 -> 0.072124756 | E36: 0.072124756 | F36: =IF(ABS(D36-E36)<0.000001,"OK","DIFF") -> OK
B37: ACC premium to undisturbed close | D37: ='Deal & Financing'!$C$31 -> 0.088345242 | E37: 0.088345242 | F37: =IF(ABS(D37-E37)<0.000001,"OK","DIFF") -> OK
B38: Premium paid over undisturbed value | D38: ='Deal & Financing'!$C$32 -> 3480.3412 | E38: 3480.3412 | F38: =IF(ABS(D38-E38)<0.5,"OK","DIFF") -> OK
B39: Market value of stakes at completion-day close | D39: ='Deal & Financing'!$C$33 -> 68043.569 | E39: 68043.569 | F39: =IF(ABS(D39-E39)<0.5,"OK","DIFF") -> OK
B40: Unlevered cost of capital (rf + βa × ERP) | D40: ='Deal & Financing'!$C$36 -> 0.12775 | E40: 0.12775 | F40: =IF(ABS(D40-E40)<0.000001,"OK","DIFF") -> OK
B41: Holdco debt / equity at cost | D41: ='Deal & Financing'!$C$37 -> 2.3625147 | E41: 2.3625147 | F41: =IF(ABS(D41-E41)<0.000001,"OK","DIFF") -> OK
...

Sheet Inputs
B1: Inputs
B2: Every hard-coded number used by the formulas. Change blue cells only.
B4: Deal terms (filed)
B5: INR per USD at completion (16-Sep-2022) | C5: 79.85 | H5: [FILED] NSE / Yahoo USDINR close
B6: Ambuja shares outstanding (crore) | C6: 198.56 | H6: [DERIVED] share capital ₹397.13 Cr / ₹2 face value
B7: Holcim stake in Ambuja sold | C7: 0.6311 | H7: [FILED] Holcim release
B8: Ambuja open-offer shares tendered (crore) | C8: 0.0727 | H8: [FILED] Business Standard, 10-Sep-2022
B9: Ambuja offer price (₹/share) | C9: 385 | H9: [FILED] Holcim release
B10: Ambuja undisturbed close 13-May-2022 (₹) | C10: 359.1 | H10: [FILED] NSE close
B11: Ambuja close at completion 16-Sep-2022 (₹) | C11: 516.7 | H11: [FILED] NSE close
B12: Ambuja's stake in ACC | C12: 0.5005 | H12: [FILED] Holcim release
B13: ACC shares outstanding (crore) | C13: 18.78 | H13: [FILED]
B14: Holcim direct stake in ACC sold | C14: 0.0448 | H14: [FILED] Holcim release
B15: ACC open-offer shares tendered (crore) | C15: 0.4061 | H15: [FILED] Business Standard, 10-Sep-2022
B16: ACC offer price (₹/share) | C16: 2300 | H16: [FILED] Holcim release
... B23: Transaction costs (% of consideration) | C23: 0.01 | H23: [ASSUMPTION] advisory, legal, stamp duty; expensed
B25: Acquisition financing (holdco)
B26: Acquisition facilities (US$ bn) | C26: 4.5 | H26: [FILED] Adani release: US$4.5bn from 14 banks
B27: of which bridge loans (US$ bn) | C27: 3.5 | H27: [FILED] Business Standard, 1-Dec-2022
B28: Term loan rate | C28: 0.075 | H28: [ASSUMPTION] USD SOFR + ~275bp
B29: Bridge loan rate (Year 1) | C29: 0.08 | H29: [ASSUMPTION]
B30: Refinanced rate (Year 2 onward) | C30: 0.075 | H30: [ASSUMPTION] bridge refinanced into 5-yr debt
B31: Holdco interest tax-deductible? (1 = yes, 0 = no) | C31: 0 | H31: [ASSUMPTION] Mauritius SPV has no taxable income; no tax consolidation in India
B32: Withholding tax on Ambuja dividends | C32: 0.05 | H32: [ASSUMPTION] India–Mauritius DTAA (>=10% holding)
B33: Withholding tax on ACC dividends | C33: 0.15 | H33: [ASSUMPTION] DTAA (<10% direct holding)
B35: Projections and cost of capital | C35: CY2021A | D35: FY2023E | E35: FY2024E | F35: FY2025E
B36: Ambuja revenue growth | D36: 0.12 | E36: 0.09 | F36: 0.08 | H36: [ASSUMPTION] Year 1 vs CY2021
B37: ACC revenue growth | D37: 0.12 | E37: 0.09 | F37: 0.08 | H37: [ASSUMPTION]
B38: Ambuja EBITDA margin | D38: 0.18 | E38: 0.2 | F38: 0.21 | H38: [ASSUMPTION] CY2021 actual 23.0%
B39: ACC EBITDA margin | D39: 0.12 | E39: 0.14 | F39: 0.15 | H39: [ASSUMPTION] CY2021 actual 18.6%
B40: Corporate tax rate | C40: 0.2517 | H40: [FILED] s.115BAA
B41: Dividend payout ratio (Ambuja & ACC) | C41: 0.2 | H41: [ASSUMPTION] in line with 2019-20 history (19%)
B42: Risk-free rate (India 10Y) | C42: 0.0725 | H42: [ASSUMPTION]
B43: Equity risk premium | C43: 0.065 | H43: [ASSUMPTION]
B44: Asset beta (Indian cement) | C44: 0.85 | H44: [ASSUMPTION] targets are net-cash, so equity beta ≈ asset beta
B45: Synergy terminal growth | C45: 0.04 | H45: [ASSUMPTION] RBI CPI target
B47: Purchase price allocation (illustrative estimates)
B48: AMBUJA step-up: ppe | C48: 3200 | H48: [ASSUMPTION] no public PPA for the holdco
B49: AMBUJA step-up: mineral rights | C49: 4500 | H49: [ASSUMPTION] no public PPA for the holdco
B50: AMBUJA step-up: brand | C50: 2800 | H50: [ASSUMPTION] no public PPA for the holdco
...

Sheet Deal & Financing
B1: Deal, sources & uses, ownership
B3: Shares acquired (crore) and consideration
B4: Ambuja shares bought from Holcim | C4: ='Inputs'!$C$6*'Inputs'!$C$7 -> 125.31122
B5: ACC shares bought from Holcim (direct) | C5: ='Inputs'!$C$13*'Inputs'!$C$14 -> 0.841344
B6: Holcim Ambuja stake | C6: =$C$4*'Inputs'!$C$9 -> 48244.818
B7: Holcim direct ACC stake | C7: =$C$5*'Inputs'!$C$16 -> 1935.0912
B8: Ambuja open offer (shares tendered) | C8: ='Inputs'!$C$8*'Inputs'!$C$9 -> 27.9895
B9: ACC open offer (shares tendered) | C9: ='Inputs'!$C$15*'Inputs'!$C$16 -> 934.03
B10: Total consideration | C10: =$C$6+$C$7+$C$8+$C$9 -> 51141.929
B11: Total consideration (US$ bn) | C11: =$C$10/'Inputs'!$C$5/100 -> 6.40475
B12: Transaction costs | C12: =$C$10*'Inputs'!$C$23 -> 511.41929
B13: Total uses | C13: =$C$10+$C$12 -> 51653.348
B15: Sources (holdco)
B16: Acquisition debt (INR) | C16: ='Inputs'!$C$26*'Inputs'!$C$5*100 -> 35932.5
B17: of which bridge | C17: ='Inputs'!$C$27*'Inputs'!$C$5*100 -> 27947.5
B18: of which term loan | C18: =$C$16-$C$17 -> 7985
B19: Sponsor equity (balancing item) | C19: =$C$13-$C$16 -> 15720.848
B20: Total sources | C20: =$C$16+$C$19 -> 51653.348
B21: Target cash cannot fund the purchase: Companies Act s.67 and ~37% minority ownership of Ambuja.
B23: Ownership after the deal
B24: Adani stake in Ambuja | C24: =($C$4+'Inputs'!$C$8)/'Inputs'!$C$6 -> 0.63146614
B25: Adani direct stake in ACC | C25: =($C$5+'Inputs'!$C$15)/'Inputs'!$C$13 -> 0.066424068
B26: Adani-controlled stake in ACC (direct + via Ambuja) | C26: =$C$25+'Inputs'!$C$12 -> 0.56692407
B27: Adani look-through economic stake in ACC | C27: =$C$24*'Inputs'!$C$12+$C$25 -> 0.38247287
B29: Premium
B30: Ambuja premium to undisturbed close | C30: ='Inputs'!$C$9/'Inputs'!$C$10-1 -> 0.072124756
B31: ACC premium to undisturbed close | C31: ='Inputs'!$C$16/'Inputs'!$C$17-1 -> 0.088345242
B32: Premium paid over undisturbed value | C32: =($C$4+'Inputs'!$C$8)*('Inputs'!$C$9-'Inputs'!$C$10)+($C$5+'Inputs'!$C$15)*('Inputs'!$C$16-'Inputs'!$C$17) -> 3480.3412
B33: Market value of stakes at completion-day close | C33: =($C$4+'Inputs'!$C$8)*'Inputs'!$C$11+($C$5+'Inputs'!$C$15)*'Inputs'!$C$18 -> 68043.569
B35: Cost of capital
B36: Unlevered cost of capital (rf + βa × ERP) | C36: ='Inputs'!$C$42+'Inputs'!$C$44*'Inputs'!$C$43 -> 0.12775
B37: Holdco debt / equity at cost | C37: =$C$16/($C$10-$C$16) -> 2.3625147
B38: Relevered beta (Hamada; no shield unless deductible) | C38: ='Inputs'!$C$44*(1+(1-'Inputs'!$C$40*'Inputs'!$C$31)*$C$37) -> 2.8581375
B39: Levered cost of equity on sponsor equity | C39: ='Inputs'!$C$42+$C$38*'Inputs'!$C$43 -> 0.25827894
B41: Valuation at offer prices
B42: 100% equity value (Ambuja + ACC minority 49.95%) | C42: ='Inputs'!$C$6*'Inputs'!$C$9+(1-'Inputs'!$C$12)*'Inputs'!$C$13*'Inputs'!$C$16 -> 98021.003
B43: Net debt 31-Dec-2021 (net cash shown negative) | C43: ='Inputs'!$C$70+'Inputs'!$C$85-'Inputs'!$C$77-'Inputs'!$C$92 -> -11095
B44: Enterprise value | C44: =$C$42+$C$43 -> 86926.003
B45: EV / EBITDA CY2021 | C45: =$C$44/('Inputs'!$C$95+'Inputs'!$C$96) -> 13.986485
B46: EV per tonne of capacity (₹) | C46: =$C$44*10/'Inputs'!$C$19 -> 12877.926
...

Sheet PPA & Goodwill
B1: Purchase price allocation and goodwill
B2: Look-through method; NCI measured at its share of identifiable net assets (Ind AS 103 option).
B4: AMBUJA — fair value of identifiable net assets
B5: Gross fair-value step-ups | C5: ='Inputs'!$C$48+'Inputs'!$C$49+'Inputs'!$C$50+'Inputs'!$C$51+'Inputs'!$C$52+'Inputs'!$C$53 -> 12530
B6: Deferred tax liability on step-ups | C6: =$C$5*'Inputs'!$C$40 -> 3153.801
B7: Book equity 31-Dec-2021 | C7: ='Inputs'!$C$68+'Inputs'!$C$69 -> 22205
B8: Less: investments eliminated (ACC stake valued separately) | C8: ='Inputs'!$C$74 -> 11774
B9: FV of identifiable net assets (Ambuja ex-ACC) | C9: =$C$7-$C$8+$C$5-$C$6 -> 19807.199
B10: Annual amortisation of step-ups | C10: ='Inputs'!$C$48/'Inputs'!$C$60+('Inputs'!$C$49+'Inputs'!$C$51+'Inputs'!$C$52)/'Inputs'!$C$61 -> 636.66667
B12: ACC — fair value of identifiable net assets
B13: Gross fair-value step-ups | C13: ='Inputs'!$C$54+'Inputs'!$C$55+'Inputs'!$C$56+'Inputs'!$C$57+'Inputs'!$C$58+'Inputs'!$C$59 -> 10390
B14: Deferred tax liability on step-ups | C14: =$C$13*'Inputs'!$C$40 -> 2615.163
B15: Book equity 31-Dec-2021 | C15: ='Inputs'!$C$83+'Inputs'!$C$84 -> 14228
B16: FV of identifiable net assets (ACC) | C16: =$C$15+$C$13-$C$14 -> 22002.837
B17: Annual amortisation of step-ups | C17: ='Inputs'!$C$54/'Inputs'!$C$60+('Inputs'!$C$55+'Inputs'!$C$57+'Inputs'!$C$58)/'Inputs'!$C$61 -> 531.33333
B19: Goodwill (look-through)
B20: ACC 100% equity at offer price | C20: ='Inputs'!$C$13*'Inputs'!$C$16 -> 43194
B21: ACC value embedded in Ambuja shares bought | C21: ='Deal & Financing'!$C$24*'Inputs'!$C$12*$C$20 -> 13651.412
B22: Consideration attributable to Ambuja ex-ACC | C22: ='Deal & Financing'!$C$6+'Deal & Financing'!$C$8-$C$21 -> 34621.396
B23: Consideration attributable to ACC (look-through) | C23: =$C$21+'Deal & Financing'!$C$7+'Deal & Financing'!$C$9 -> 16520.533
B24: Adani share of Ambuja FV net assets | C24: ='Deal & Financing'!$C$24*$C$9 -> 12507.575
B25: Adani share of ACC FV net assets | C25: ='Deal & Financing'!$C$27*$C$16 -> 8415.4882
B26: Goodwill — Ambuja | C26: =$C$22-$C$24 -> 22113.82
B27: Goodwill — ACC | C27: =$C$23-$C$25 -> 8105.0449
B28: Total goodwill | C28: =$C$26+$C$27 -> 30218.865
B29: Goodwill as % of consideration | C29: =$C$28/'Deal & Financing'!$C$10 -> 0.59088239
B30: New intangibles recognised (incl. brands) | C30: ='Inputs'!$C$49+'Inputs'!$C$51+'Inputs'!$C$52+'Inputs'!$C$50+'Inputs'!$C$55+'Inputs'!$C$57+'Inputs'!$C$58+'Inputs'!$C$56 -> 16520

Sheet Projections
B1: Standalone projections
B2: Ambuja excludes dividends from ACC (intra-group). Cash, interest expense and D&A % of revenue held at CY2021 levels.
B4: Treasury yield (derived)
B5: ACC dividend received by Ambuja in CY2021 | C5: ='Inputs'!$C$94*'Inputs'!$C$13*'Inputs'!$C$12 -> 131.59146
B6: Treasury yield on cash | C6: =('Inputs'!$C$67-$C$5+'Inputs'!$C$82)/('Inputs'!$C$77+'Inputs'!$C$92) -> 0.030453555
B8: AMBUJA standalone | C8: CY2021A | D8: FY2023E | E8: FY2024E | F8: FY2025E
B9: Revenue | C9: ='Inputs'!$C$64 -> 13979 | D9: =C9*(1+'Inputs'!$D$36) -> 15656.48 | E9: =D9*(1+'Inputs'!$E$36) -> 17065.563 | F9: =E9*(1+'Inputs'!$F$36) -> 18430.808
B10: EBITDA | D10: =D9*'Inputs'!$D$38 -> 2818.1664 | E10: =E9*'Inputs'!$E$38 -> 3413.1126 | F10: =F9*'Inputs'!$F$38 -> 3870.4697
B11: Depreciation & amortisation | D11: =D9*'Inputs'!$C$65/'Inputs'!$C$64 -> 618.24 | E11: =E9*'Inputs'!$C$65/'Inputs'!$C$64 -> 673.8816 | F11: =F9*'Inputs'!$C$65/'Inputs'!$C$64 -> 727.79213
B12: Treasury income | D12: =$C$6*'Inputs'!$C$77 -> 126.96087 | E12: =$C$6*'Inputs'!$C$77 -> 126.96087 | F12: =$C$6*'Inputs'!$C$77 -> 126.96087
B13: Interest expense | D13: ='Inputs'!$C$66 -> 91 | E13: ='Inputs'!$C$66 -> 91 | F13: ='Inputs'!$C$66 -> 91
B14: Profit before tax | D14: =D10-D11+D12-D13 -> 2235.8873 | E14: =E10-E11+E12-E13 -> 2775.1919 | F14: =F10-F11+F12-F13 -> 3178.6385
B15: Net income | D15: =D14*(1-'Inputs'!$C$40) -> 1673.1144 | E15: =E14*(1-'Inputs'!$C$40) -> 2076.6761 | F15: =F14*(1-'Inputs'!$C$40) -> 2378.5752
B17: ACC standalone | C17: CY2021A | D17: FY2023E | E17: FY2024E | F17: FY2025E
B18: Revenue | C18: ='Inputs'!$C$79 -> 16151 | D18: =C18*(1+'Inputs'!$D$37) -> 18089.12 | E18: =D18*(1+'Inputs'!$E$37) -> 19717.141 | F18: =E18*(1+'Inputs'!$F$37) -> 21294.512
B19: EBITDA | D19: =D18*'Inputs'!$D$39 -> 2170.6944 | E19: =E18*'Inputs'!$E$39 -> 2760.3997 | F19: =F18*'Inputs'!$F$39 -> 3194.1768
B20: Depreciation & amortisation | D20: =D18*'Inputs'!$C$80/'Inputs'!$C$79 -> 668.64 | E20: =E18*'Inputs'!$C$80/'Inputs'!$C$79 -> 728.8176 | F20: =F18*'Inputs'!$C$80/'Inputs'!$C$79 -> 787.12301
B21: Treasury income | D21: =$C$6*'Inputs'!$C$92 -> 225.44767 | E21: =$C$6*'Inputs'!$C$92 -> 225.44767 | F21: =$C$6*'Inputs'!$C$92 -> 225.44767
B22: Interest expense | D22: ='Inputs'!$C$81 -> 55 | E22: ='Inputs'!$C$81 -> 55 | F22: ='Inputs'!$C$81 -> 55
B23: Profit before tax | D23: =D19-D20+D21-D22 -> 1672.5021 | E23: =E19-E20+E21-E22 -> 2202.0298 | F23: =F19-F20+F21-F22 -> 2577.5015
B24: Net income | D24: =D23*(1-'Inputs'!$C$40) -> 1251.5333 | E24: =E23*(1-'Inputs'!$C$40) -> 1647.7789 | F24: =F23*(1-'Inputs'!$C$40) -> 1928.7444
B26: Dividends | C26: CY2021A | D26: FY2023E | E26: FY2024E | F26: FY2025E
B27: ACC dividends paid | D27: ='Inputs'!$C$41*D24 -> 250.30666 | E27: ='Inputs'!$C$41*E24 -> 329.55578 | F27: ='Inputs'!$C$41*F24 -> 385.74887
B28: of which to Ambuja | D28: =D27*'Inputs'!$C$12 -> 125.27848 | E28: =E27*'Inputs'!$C$12 -> 164.94267 | F28: =F27*'Inputs'!$C$12 -> 193.06731
B29: Ambuja dividends paid (ACC dividends passed through, s.80M) | D29: ='Inputs'!$C$41*(D15+D28) -> 359.67859 | E29: ='Inputs'!$C$41*(E15+E28) -> 448.32375 | F29: ='Inputs'!$C$41*(F15+F28) -> 514.3285

Sheet Synergies
B1: Synergies
B2: [ASSUMPTION] Model estimates, not company guidance. Edit run-rates and phasing here.
B4: Phasing (% of run-rate) | C4: Run-rate | D4: FY2023E | E4: FY2024E | F4: FY2025E
B5: Procurement (fly ash, gypsum, slag, coal) | C5: 850 | D5: 0.3 | E5: 0.7 | F5: 1
B6: Logistics & freight (route rationalisation, ports) | C6: 620 | D6: 0.2 | E6: 0.6 | F6: 1
B7: SG&A and shared services | C7: 480 | D7: 0.4 | E7: 0.8 | F7: 1
B8: Energy (fuel mix, WHRS, renewables) | C8: 380 | D8: 0.15 | E8: 0.5 | F8: 1
B9: Plant optimisation (clinker factor) | C9: 270 | D9: 0.1 | E9: 0.45 | F9: 1
B10: Revenue: cross-selling into new regions (EBITDA impact) | C10: 310 | D10: 0.1 | E10: 0.4 | F10: 1
B11: Revenue: pricing discipline (EBITDA impact) | C11: 190 | D11: 0.25 | E11: 0.65 | F11: 1
B13: Pre-tax synergies (EBITDA) | C13: Run-rate | D13: FY2023E | E13: FY2024E | F13: FY2025E
B14: Procurement (fly ash, gypsum, slag, coal) | C14: =C5 -> 850 | D14: =C5*D5 -> 255 | E14: =C5*E5 -> 595 | F14: =C5*F5 -> 850
B15: Logistics & freight (route rationalisation, ports) | C15: =C6 -> 620 | D15: =C6*D6 -> 124 | E15: =C6*E6 -> 372 | F15: =C6*F6 -> 620
B16: SG&A and shared services | C16: =C7 -> 480 | D16: =C7*D7 -> 192 | E16: =C7*E7 -> 384 | F16: =C7*F7 -> 480
B17: Energy (fuel mix, WHRS, renewables) | C17: =C8 -> 380 | D17: =C8*D8 -> 57 | E17: =C8*E8 -> 190 | F17: =C8*F8 -> 380
B18: Plant optimisation (clinker factor) | C18: =C9 -> 270 | D18: =C9*D9 -> 27 | E18: =C9*E9 -> 121.5 | F18: =C9*F9 -> 270
B19: Revenue: cross-selling into new regions (EBITDA impact) | C19: =C10 -> 310 | D19: =C10*D10 -> 31 | E19: =C10*E10 -> 124 | F19: =C10*F10 -> 310
B20: Revenue: pricing discipline (EBITDA impact) | C20: =C11 -> 190 | D20: =C11*D11 -> 47.5 | E20: =C11*E11 -> 123.5 | F20: =C11*F11 -> 190
B21: Total synergies | C21: =C14+C15+C16+C17+C18+C19+C20 -> 3100 | D21: =D14+D15+D16+D17+D18+D19+D20 -> 733.5 | E21: =E14+E15+E16+E17+E18+E19+E20 -> 1910 | F21: =F14+F15+F16+F17+F18+F19+F20 -> 3100
B22: Costs to achieve phasing | C22: 2800 | D22: 0.6 | E22: 0.4 | F22: 0
B23: Costs to achieve (one-off, pre-tax) | D23: =C22*D22 -> 1680 | E23: =C22*E22 -> 1120 | F23: =C22*F22 -> 0
B25: NPV at the unlevered cost of capital | C25: Run-rate | D25: FY2023E | E25: FY2024E | F25: FY2025E
B26: Discount factor | D26: =(1+'Deal & Financing'!$C$36)^1 -> 1.12775 | E26: =(1+'Deal & Financing'!$C$36)^2 -> 1.2718201 | F26: =(1+'Deal & Financing'!$C$36)^3 -> 1.4342951
B27: PV of after-tax synergies | D27: =D21*(1-'Inputs'!$C$40)/D26 -> 486.70188 | E27: =E21*(1-'Inputs'!$C$40)/E26 -> 1123.7855 | F27: =F21*(1-'Inputs'!$C$40)/F26 -> 1617.3311
B28: PV of after-tax costs to achieve | D28: =D23*(1-'Inputs'!$C$40)/D26 -> 1114.7364 | E28: =E23*(1-'Inputs'!$C$40)/E26 -> 658.97372 | F28: =F23*(1-'Inputs'!$C$40)/F26 -> 0
B29: PV of terminal value (run-rate after tax, growing) | C29: =C21*(1-'Inputs'!$C$40)*(1+'Inputs'!$C$45)/('Deal & Financing'!$C$36-'Inputs'!$C$45)/F26 -> 19168.368
B30: Gross synergy NPV | C30: =SUM($D$27:$F$27)+$C$29 -> 22396.187
B31: Less: PV of costs to achieve | C31: =SUM($D$28:$F$28) -> 1773.7101
B32: Net synergy NPV | C32: =$C$30-$C$31 -> 20622.477
B33: Terminal value share of gross NPV | C33: =$C$29/$C$30 -> 0.85587643

Sheet Pro Forma & Returns
B1: Pro forma earnings, holdco cash and returns
B3: Consolidated income statement (100%) | D3: FY2023E | E3: FY2024E | F3: FY2025E
B4: Revenue (Ambuja + ACC) | D4: ='Projections'!$D$9+'Projections'!$D$18 -> 33745.6 | E4: ='Projections'!$E$9+'Projections'!$E$18 -> 36782.704 | F4: ='Projections'!$F$9+'Projections'!$F$18 -> 39725.32
B5: EBITDA incl. synergies, less costs to achieve | D5: ='Projections'!$D$10+'Projections'!$D$19+'Synergies'!$D$21-'Synergies'!$D$23 -> 4042.3608 | E5: ='Projections'!$E$10+'Projections'!$E$19+'Synergies'!$E$21-'Synergies'!$E$23 -> 6963.5124 | F5: ='Projections'!$F$10+'Projections'!$F$19+'Synergies'!$F$21-'Synergies'!$F$23 -> 10164.647
B6: PPA amortisation — Ambuja (incl. inventory in Year 1) | D6: ='PPA & Goodwill'!$C$10+'Inputs'!$C$53 -> 816.66667 | E6: ='PPA & Goodwill'!$C$10 -> 636.66667 | F6: ='PPA & Goodwill'!$C$10 -> 636.66667
B7: PPA amortisation — ACC (incl. inventory in Year 1) | D7: ='PPA & Goodwill'!$C$17+'Inputs'!$C$59 -> 751.33333 | E7: ='PPA & Goodwill'!$C$17 -> 531.33333 | F7: ='PPA & Goodwill'!$C$17 -> 531.33333
B8: D&A incl. PPA | D8: ='Projections'!$D$11+'Projections'!$D$20+D6+D7 -> 2854.88 | E8: ='Projections'!$E$11+'Projections'!$E$20+E6+E7 -> 2570.6992 | F8: ='Projections'!$F$11+'Projections'!$F$20+F6+F7 -> 2682.9151
B9: Treasury income | D9: ='Projections'!$D$12+'Projections'!$D$21 -> 352.40854 | E9: ='Projections'!$E$12+'Projections'!$E$21 -> 352.40854 | F9: ='Projections'!$F$12+'Projections'!$F$21 -> 352.40854
B10: Target interest expense | D10: ='Projections'!$D$13+'Projections'!$D$22 -> 146 | E10: ='Projections'!$E$13+'Projections'!$E$22 -> 146 | F10: ='Projections'!$F$13+'Projections'!$F$22 -> 146
B11: Holdco acquisition interest | D11: ='Deal & Financing'!$C$18*'Inputs'!$C$28+'Deal & Financing'!$C$17*'Inputs'!$C$29 -> 2834.675 | E11: =E32*'Inputs'!$C$30 -> 2694.9375 | F11: =F32*'Inputs'!$C$30 -> 2694.9375
B12: Profit before tax | D12: =D5-D8+D9-D10-D11 -> -1440.7857 | E12: =E5-E8+E9-E10-E11 -> 1904.2842 | F12: =F5-F8+F9-F10-F11 -> 4993.2024
B13: Holdco interest after any tax shield | D13: =D11*(1-'Inputs'!$C$40*'Inputs'!$C$31) -> 2834.675 | E13: =E11*(1-'Inputs'!$C$40*'Inputs'!$C$31) -> 2694.9375 | F13: =F11*(1-'Inputs'!$C$40*'Inputs'!$C$31) -> 2694.9375
B14: Tax (no shield on holdco interest unless deductible) | D14: =(D12+D11)*'Inputs'!$C$40-D11*'Inputs'!$C$40*'Inputs'!$C$31 -> 350.84195 | E14: =(E12+E11)*'Inputs'!$C$40-E11*'Inputs'!$C$40*'Inputs'!$C$31 -> 1157.6241 | F14: =(F12+F11)*'Inputs'!$C$40-F11*'Inputs'!$C$40*'Inputs'!$C$31 -> 1935.1048
B15: Consolidated net income | D15: =D12-D14 -> -1791.6276 | E15: =E12-E14 -> 746.66009 | F15: =F12-F14 -> 3058.0976
B17: Attribution to Adani | D17: FY2023E | E17: FY2024E | F17: FY2025E
B18: Adani share of synergies (EBITDA-weighted look-through) | D18: =('Deal & Financing'!$C$24*'Projections'!$D$10+'Deal & Financing'!$C$27*'Projections'!$D$19)/('Projections'!$D$10+'Projections'!$D$19) -> 0.52312712 | E18: =('Deal & Financing'!$C$24*'Projections'!$E$10+'Deal & Financing'!$C$27*'Projections'!$E$19)/('Projections'!$E$10+'Projections'!$E$19) -> 0.52013228 | F18: =('Deal & Financing'!$C$24*'Projections'!$F$10+'Deal & Financing'!$C$27*'Projections'!$F$19)/('Projections'!$F$10+'Projections'!$F$19) -> 0.51888747
B19: Share of standalone net income | D19: ='Deal & Financing'!$C$24*'Projections'!$D$15+'Deal & Financing'!$C$27*'Projections'!$D$24 -> 1535.1926 | E19: ='Deal & Financing'!$C$24*'Projections'!$E$15+'Deal & Financing'!$C$27*'Projections'!$E$24 -> 1941.5814 | F19: ='Deal & Financing'!$C$24*'Projections'!$F$15+'Deal & Financing'!$C$27*'Projections'!$F$24 -> 2239.6821
B20: Share of synergies after tax | D20: =D18*'Synergies'!$D$21*(1-'Inputs'!$C$40) -> 287.13299 | E20: =E18*'Synergies'!$E$21*(1-'Inputs'!$C$40) -> 743.40062 | F20: =F18*'Synergies'!$F$21*(1-'Inputs'!$C$40) -> 1203.6788
B21: Share of costs to achieve after tax | D21: =D18*'Synergies'!$D$23*(1-'Inputs'!$C$40) -> 657.64612 | E21: =E18*'Synergies'!$E$23*(1-'Inputs'!$C$40) -> 435.92078 | F21: =F18*'Synergies'!$F$23*(1-'Inputs'!$C$40) -> 0
B22: Share of PPA amortisation after tax | D22: =('Deal & Financing'!$C$24*D6+'Deal & Financing'!$C$27*D7)*(1-'Inputs'!$C$40) -> 600.93126 | E22: =('Deal & Financing'!$C$24*E6+'Deal & Financing'!$C$27*E7)*(1-'Inputs'!$C$40) -> 452.91159 | F22: =('Deal & Financing'!$C$24*F6+'Deal & Financing'!$C$27*F7)*(1-'Inputs'!$C$40) -> 452.91159
B23: Adani-attributable net income | D23: =D19+D20-D21-D22-D13 -> -2270.9267 | E23: =E19+E20-E21-E22-E13 -> -898.78789 | F23: =F19+F20-F21-F22-F13 -> 295.51179
B24: Non-controlling interests' share | D24: =D15-D23 -> 479.29914 | E24: =E15-E23 -> 1645.448 | F24: =F15-F23 -> 2762.5858
B26: Holdco cash and debt | D26: FY2023E | E26: FY2024E | F26: FY2025E
B27: Dividends received, net of withholding tax | D27: ='Deal & Financing'!$C$24*'Projections'!$D$29*(1-'Inputs'!$C$32)+'Deal & Financing'!$C$25*'Projections'!$D$27*(1-'Inputs'!$C$33) -> 229.90103 | E27: ='Deal & Financing'!$C$24*'Projections'!$E$29*(1-'Inputs'!$C$32)+'Deal & Financing'!$C$25*'Projections'!$E$27*(1-'Inputs'!$C$33) -> 287.55308 | F27: ='Deal & Financing'!$C$24*'Projections'!$F$29*(1-'Inputs'!$C$32)+'Deal & Financing'!$C$25*'Projections'!$F$27*(1-'Inputs'!$C$33) -> 330.32153
B28: Holdco cash flow (dividends − interest) | D28: =D27-D13 -> -2604.774 | E28: =E27-E13 -> -2407.3844 | F28: =F27-F13 -> -2364.616
B29: Dividend / interest cover | D29: =D27/D13 -> 0.081103136 | E29: =E27/E13 -> 0.1067012 | F29: =F27/F13 -> 0.12257113
B30: Sponsor top-up needed | D30: =MAX(-D28,0) -> 2604.774 | E30: =MAX(-E28,0) -> 2407.3844 | F30: =MAX(-F28,0) -> 2364.616
B31: Debt repaid from surplus | D31: =MAX(D28,0) -> 0 | E31: =MAX(E28,0) -> 0 | F31: =MAX(F28,0) -> 0
B32: Holdco debt — opening | D32: ='Deal & Financing'!$C$16 -> 35932.5 | E32: =D33 -> 35932.5 | F32: =E33 -> 35932.5
B33: Holdco debt — closing | D33: =D32-D31 -> 35932.5 | E33: =E32-E31 -> 35932.5 | F33: =F32-F31 -> 35932.5
B34: Sponsor equity invested — opening | D34: ='Deal & Financing'!$C$19 -> 15720.848 | E34: =D34+D30 -> 18325.622 | F34: =E34+E30 -> 20733.007
B36: Returns | D36: FY2023E | E36: FY2024E | F36: FY2025E
B37: Return on sponsor equity (attributable NI / equity invested) | D37: =D23/D34 -> -0.1444532 | E37: =E23/E34 -> -0.049045423 | F37: =F23/F34 -> 0.014253205
B38: Levered cost of equity | D38: ='Deal & Financing'!$C$39 -> 0.25827894 | E38: ='Deal & Financing'!$C$39 -> 0.25827894 | F38: ='Deal & Financing'!$C$39 -> 0.25827894
B39: Cash earnings before acquisition financing | D39: =D23+D13+D22+D21 -> 1822.3256 | E39: =E23+E13+E22+E21 -> 2684.982 | F39: =F23+F13+F22+F21 -> 3443.3609
B40: Cash ROIC on total investment | D40: =D39/'Deal & Financing'!$C$13 -> 0.035279913 | E40: =E39/'Deal & Financing'!$C$13 -> 0.051980793 | F40: =F39/'Deal & Financing'!$C$13 -> 0.066662879
B41: Unlevered cost of capital | D41: ='Deal & Financing'!$C$36 -> 0.12775 | E41: ='Deal & Financing'!$C$36 -> 0.12775 | F41: ='Deal & Financing'!$C$36 -> 0.12775
B42: Breakeven in-year synergies for ROIC = cost of capital | D42: =MAX(0,('Deal & Financing'!$C$36*'Deal & Financing'!$C$13-(D39-D20))/(D18*(1-'Inputs'!$C$40))) -> 12935.099 | E42: =MAX(0,('Deal & Financing'!$C$36*'Deal & Financing'!$C$13-(E39-E20))/(E18*(1-'Inputs'!$C$40))) -> 11965.454 | F42: =MAX(0,('Deal & Financing'!$C$36*'Deal & Financing'!$C$13-(F39-F20))/(F18*(1-'Inputs'!$C$40))) -> 11226.419
B44: Value creation: Adani's share of synergy NPV vs premium paid
B45: Adani share of net synergy NPV (final-year look-through weight) | C45: =F18*'Synergies'!$C$32 -> 10700.745
...

Sheet Balance Sheet
B1: Pro forma balance sheet at close
B2: 31-Dec-2021 audited balance sheets used as the closing proxy.
B4: Assets
B5: Fixed assets & CWIP (incl. PP&E step-up) | C5: ='Inputs'!$C$72+'Inputs'!$C$73+'Inputs'!$C$87+'Inputs'!$C$88+'Inputs'!$C$48+'Inputs'!$C$54 -> 22557
B6: Acquired intangibles | C6: ='PPA & Goodwill'!$C$30 -> 16520
B7: Goodwill | C7: ='PPA & Goodwill'!$C$28 -> 30218.865
B8: Inventories (incl. step-up) | C8: ='Inputs'!$C$75+'Inputs'!$C$90+'Inputs'!$C$53+'Inputs'!$C$59 -> 3137
B9: Trade receivables | C9: ='Inputs'!$C$76+'Inputs'!$C$91 -> 757
B10: Cash (targets; holdco holds none) | C10: ='Inputs'!$C$77+'Inputs'!$C$92 -> 11572
B11: Investments (Ambuja's ACC stake eliminated) | C11: ='Inputs'!$C$89 -> 193
B12: Other assets | C12: ='Inputs'!$C$78+'Inputs'!$C$93 -> 5512
B13: Total assets | C13: =$C$5+$C$6+$C$7+$C$8+$C$9+$C$10+$C$11+$C$12 -> 90466.865
B15: Liabilities and equity
B16: Acquisition debt (holdco) | C16: ='Deal & Financing'!$C$16 -> 35932.5
B17: Target borrowings & leases | C17: ='Inputs'!$C$70+'Inputs'!$C$85 -> 477
B18: Deferred tax on step-ups | C18: ='PPA & Goodwill'!$C$6+'PPA & Goodwill'!$C$14 -> 5768.964
B19: Other liabilities | C19: ='Inputs'!$C$71+'Inputs'!$C$86 -> 12192
B20: Adani equity (sponsor equity less expensed costs) | C20: ='Deal & Financing'!$C$19-'Deal & Financing'!$C$12 -> 15209.429
B21: Non-controlling interests | C21: =(1-'Deal & Financing'!$C$24)*'PPA & Goodwill'!$C$9+(1-'Deal & Financing'!$C$27)*'PPA & Goodwill'!$C$16 -> 20886.972
B22: Total liabilities & equity | C22: =$C$16+$C$17+$C$18+$C$19+$C$20+$C$21 -> 90466.865
B24: Credit metrics at close
B25: Consolidated gross debt | C25: =$C$16+$C$17 -> 36409.5
B26: Gross debt / CY2021 EBITDA | C26: =$C$25/('Inputs'!$C$95+'Inputs'!$C$96) -> 5.8583266
B27: Net debt / CY2021 EBITDA | C27: =($C$25-$C$10)/('Inputs'!$C$95+'Inputs'!$C$96) -> 3.9963797
B28: Holdco loan-to-value at cost | C28: ='Deal & Financing'!$C$16/'Deal & Financing'!$C$10 -> 0.70260353
B29: Holdco loan-to-value at completion-day market prices | C29: ='Deal & Financing'!$C$16/'Deal & Financing'!$C$33 -> 0.52808076

Sheet Precedents
B1: Precedent transactions — Indian cement (announced before May-2022)
B2: EV/tonne is the sector benchmark. Most precedents were asset or unlisted deals, so control premiums are not comparable; EV/EBITDA was not reliably disclosed.
B4: Date | C4: Acquirer | D4: Target | E4: Capacity (MTPA) | F4: EV (₹ Cr) | G4: INR/USD | H4: EV/t (₹) | I4: EV/t (US$) | J4: Note | K4: Source
B5: Sep-2013 | C5: UltraTech Cement | D5: Jaypee Gujarat unit | E5: 4.8 | F5: 3800 | G5: 63.16 | H5: =F5*10/E5 -> 7916.6667 | I5: =H5/G5 -> 125.34304 | K5: Business Standard, 12-Sep-2013 — https://www.business-standard.com/article/companies/birla-buys-jaypee-s-gujarat-cement-unit-for-rs-3-800-cr-113091200054_1.html
B6: Mar-2016 | C6: UltraTech Cement | D6: Jaiprakash Associates (6 plants) | E6: 21.2 | F6: 16189 | G6: 66.37 | H6: =F6*10/E6 -> 7636.3208 | I6: =H6/G6 -> 115.05681 | J6: Seller deleveraging; EV as revised from ₹15,900 Cr | K6: Business Standard, 5-Jul-2016 — https://www.business-standard.com/article/markets/jp-deal-big-leap-for-ultratech-116070501043_1.html
B7: Jul-2016 | C7: Nirma | D7: Lafarge India | E7: 11 | F7: 9400 | G7: 67.13 | H7: =F7*10/E7 -> 8545.4545 | I7: =H7/G7 -> 127.2971 | K7: Business Standard, 11-Jul-2016 — https://www.business-standard.com/article/companies/nirma-cements-1-4-bn-lafarge-india-buyout-116071100403_1.html
B8: May-2018 | C8: UltraTech Cement | D8: Century Textiles (cement) | E8: 14.6 | F8: 8621 | G8: 67.97 | H8: =F8*10/E8 -> 5904.7945 | I8: =H8/G8 -> 86.87354 | K8: Legally India, 22-May-2018 (EV) — https://www.legallyindia.com/corporatemna/trilegal-khaitan-vaish-on-ultratech-cem-s-buy-of-century-textile-s-cement-biz-20180522-9362 ; capacity per CARE Ratings report on UltraTech
B9: Nov-2018 | C9: UltraTech Cement | D9: Binani Cement | E9: 11 | F9: 7900 | G9: 71.69 | H9: =F9*10/E9 -> 7181.8182 | I9: =H9/G9 -> 100.1788 | J9: Distressed (IBC); capacity incl. ~5 MTPA overseas | K9: Business Standard, 25-Dec-2019 (Kotak estimate of EV) — https://www.business-standard.com/amp/article/companies/ultratech-cement-street-watchful-on-valuations-of-new-acquisition-119122500555_1.html
B10: Feb-2020 | C10: Nuvoco Vistas (Nirma) | D10: Emami Cement | E10: 8.3 | F10: 5500 | G10: 71.28 | H10: =F10*10/E10 -> 6626.506 | I10: =H10/G10 -> 92.96445 | K10: Nuvoco press release, Feb-2020 — https://admin.nuvoco.com/public/MediaRalationsDetails/Nirma%20Group%20announces%20the%20acquisition%20of%20Emami%20Cement%20-%20Feb%202020.pdf
B12: Mean EV/t (US$), all | C12: =AVERAGE(I5:I10) -> 107.95229
B13: Median EV/t (US$), all | C13: =MEDIAN(I5:I10) -> 107.61781
B14: Median EV/t (US$), excluding distressed | C14: =MEDIAN(I5,I6,I7,I8,I10) -> 115.05681
B15: This deal EV/t (US$) | C15: ='Deal & Financing'!$C$47 -> 161.27647
B16: This deal vs median (ex-distressed) | C16: =$C$15/$C$14-1 -> 0.40171162

Sheet Sensitivity
B1: Sensitivity analysis — STATIC OUTPUT FROM PYTHON
B2: Each cell is a full re-run of the Python model with the stated input changed (python run_model.py regenerates this tab).
B4: Offer price (both companies) — FY2025E
B5: Price vs actual | C5: Ambuja price (₹) | D5: Ambuja premium | E5: Consideration | F5: Sponsor equity | G5: Goodwill | H5: Cash ROIC | I5: ROE | J5: Value created
B6: 0.95 | C6: 365.75 | D6: 0.018518519 | E6: 48584.832 | F6: 13138.181 | G6: 27661.769 | H6: 0.070171451 | I6: 0.016281337 | J6: 9291.6516
B7: 1 | C7: 385 | D7: 0.072124756 | E7: 51141.929 | F7: 15720.848 | G7: 30218.865 | H7: 0.066662879 | I7: 0.014253205 | J7: 6708.9841
B8: 1.05 | C8: 404.25 | D8: 0.12573099 | E8: 53699.025 | F8: 18303.516 | G8: 32775.962 | H8: 0.063488456 | I8: 0.012674383 | J8: 4126.3167
B9: 1.1 | C9: 423.5 | D9: 0.17933723 | E9: 56256.122 | F9: 20886.183 | G9: 35333.058 | H9: 0.060602617 | I9: 0.011410452 | J9: 1543.6493
B10: 1.15 | C10: 442.75 | D10: 0.23294347 | E10: 58813.218 | F10: 23468.85 | G10: 37890.155 | H10: 0.057967721 | I10: 0.010375749 | J10: -1039.0181
B11: 1.2 | C11: 462 | D11: 0.28654971 | E11: 61370.315 | F11: 26051.518 | G11: 40447.251 | H11: 0.055552399 | I11: 0.0095130979 | J11: -3621.6855
B13: Holdco refinancing rate — FY2025E
B14: Refi rate | C14: Holdco interest | D14: Attributable NI | E14: ROE | F14: Dividend / interest
B15: 0.06 | C15: 2155.95 | D15: 834.49929 | E15: 0.041324082 | F15: 0.15321391
B16: 0.065 | C16: 2335.6125 | D16: 654.83679 | E16: 0.032141309 | F16: 0.14142823
B17: 0.07 | C17: 2515.275 | D17: 475.17429 | E17: 0.023119075 | F17: 0.13132621
B18: 0.075 | C18: 2694.9375 | D18: 295.51179 | E18: 0.014253205 | F18: 0.12257113
B19: 0.08 | C19: 2874.6 | D19: 115.84929 | E19: 0.0055396703 | F19: 0.11491043
B20: 0.085 | C20: 3054.2625 | D20: -63.813207 | E20: -0.0030254222 | F20: 0.108151
B21: 0.09 | C21: 3233.925 | D21: -243.47571 | E21: -0.011445834 | F21: 0.10214261
B22: 0.095 | C22: 3413.5875 | D22: -423.13821 | E22: -0.0197252 | F22: 0.096766682
B24: EBITDA margin (both companies, all years) — FY2025E
B25: Change (bp) | C25: Cash ROIC | D25: ROE
B26: -300 | C26: 0.058255412 | D26: -0.0066581538
B27: -200 | C27: 0.061049859 | D27: 0.00026823007
B28: -100 | C28: 0.063852827 | D28: 0.0072397984
B29: 0 | C29: 0.066662879 | D29: 0.014253205
B30: 100 | C30: 0.069478883 | D30: 0.021305845
B31: 200 | C31: 0.072299937 | D31: 0.028395666
B32: 300 | C32: 0.075125312 | D32: 0.035521037
B34: Holdco interest tax shield — FY2025E
B35: Deductible? | C35: Attributable NI | D35: ROE | E35: Levered Ke
B36: No | C36: 295.51179 | D36: 0.014253205 | E36: 0.25827894
B37: Yes | C37: 973.82756 | D37: 0.050349896 | E37: 0.22542481
B39: Net value created for Adani (₹ Cr): offer price × run-rate synergies
B40: Price \ Synergies | C40: 0 | D40: 1000 | E40: 2000 | F40: 3100 | G40: 4000 | H40: 5000
B41: 0.95 | C41: -2329.4491 | D41: 1419.2931 | E41: 5168.0352 | F41: 9291.6516 | G41: 12665.519 | H41: 16414.262
B42: 1 | C42: -4912.1165 | D42: -1163.3743 | E42: 2585.3678 | F42: 6708.9841 | G42: 10082.852 | H42: 13831.594
B43: 1.05 | C43: -7494.7839 | D43: -3746.0417 | E43: 2.7003923 | F43: 4126.3167 | G43: 7500.1847 | H43: 11248.927
B44: 1.1 | C44: -10077.451 | D44: -6328.7091 | E44: -2579.967 | F44: 1543.6493 | G44: 4917.5173 | H44: 8666.2594
B45: 1.15 | C45: -12660.119 | D45: -8911.3766 | E45: -5162.6344 | F45: -1039.0181 | G45: 2334.8498 | H45: 6083.592
...

Sheet Historicals
B1: Historical standalone financials (filed)
B2: Source: company filings via Screener.in. Year ended 31 December.
B4: Ambuja Cements
B5: INR crore | C5: CY2019 | D5: CY2020 | E5: CY2021 | F5: Check: EBITDA = revenue − opex
B6: Revenue | C6: 11668 | D6: 11372 | E6: 13979
B7: Operating expenses | C7: 9519 | D7: 8725 | E7: 10764
B8: Ebitda | C8: 2149 | D8: 2647 | E8: 3215
B9: Other income normal | C9: 424 | D9: 371 | E9: 281
B10: Exceptional items | C10: 3 | D10: 1 | E10: -66
B11: Interest expense | C11: 84 | D11: 83 | E11: 91
B12: Depreciation | C12: 544 | D12: 521 | E12: 552
B13: Pbt | C13: 1948 | D13: 2414 | E13: 2788
B14: Net income | C14: 1529 | D14: 1790 | E14: 2083
B15: Eps | C15: 7.7 | D15: 9.02 | E15: 10.49
B16: Dividend payout pct | C16: 19 | D16: 200 | E16: 60
B17: EBITDA tie-out (should be 0) | C17: =C6-C7-C8 -> 0 | D17: =D6-D7-D8 -> 0 | E17: =E6-E7-E8 -> 0
B19: ACC Ltd
B20: INR crore | C20: CY2019 | D20: CY2020 | E20: CY2021 | F20: Check: EBITDA = revenue − opex
B21: Revenue | C21: 15657 | D21: 13785 | E21: 16151
B22: Operating expenses | C22: 13247 | D22: 11432 | E22: 13151
B23: Ebitda | C23: 2409 | D23: 2352 | E23: 3000
B24: Other income normal | C24: 287 | D24: 204 | E24: 203
B25: Exceptional items | C25: 24 | D25: -176 | E25: -91
B26: Interest expense | C26: 86 | D26: 57 | E26: 55
B27: Depreciation | C27: 603 | D27: 635 | E27: 597
B28: Pbt | C28: 2031 | D28: 1688 | E28: 2460
B29: Net income | C29: 1359 | D29: 1415 | E29: 1820
B30: Eps | C30: 72.36 | D30: 75.35 | E30: 96.93
B31: Dividend payout pct | C31: 19 | D31: 19 | E31: 60
B32: EBITDA tie-out (should be 0) | C32: =C21-C22-C23 -> 1 | D32: =D21-D22-D23 -> 1 | E32: =E21-E22-E23 -> 0
